Workbook
Name Slicer_City: #N/A
Name Slicer_Month: #N/A
Name Slicer_Payment_Method: #N/A
Name Slicer_Product: #N/A
Name Slicer_Purchase_Type: #N/A

Sheet Raw Data
A1: Order ID | B1: Date | C1: Product | D1: Price | E1: Quantity | F1: Purchase Type | G1: Payment Method | H1: Manager | I1: City
A2: 10452 | B2: 44753 | C2: Fries | D2: 3.49 | E2: 573.07 | F2: Online | G2: Gift Card | H2: Tom Jackson | I2: London
A3: 10453 | B3: 44753 | C3: Beverages | D3: 2.95 | E3: 745.76 | F3: Online | G3: Gift Card | H3: Pablo Perez | I3: Madrid
A4: 10454 | B4: 44753 | C4: Sides & Other | D4: 4.99 | E4: 200.4 | F4: In-store | G4: Gift Card | H4: Joao Silva | I4: Lisbon
A5: 10455 | B5: 44784 | C5: Burgers | D5: 12.99 | E5: 569.67 | F5: In-store | G5: Credit Card | H5: Walter Muller | I5: Berlin
A6: 10456 | B6: 44784 | C6: Chicken Sandwiches | D6: 9.95 | E6: 201.01 | F6: In-store | G6: Credit Card | H6: Walter Muller | I6: Berlin
A7: 10457 | B7: 44784 | C7: Fries | D7: 3.49 | E7: 573.07 | F7: In-store | G7: Credit Card | H7: Remy Monet | I7: Paris
A8: 10459 | B8: 44784 | C8: Sides & Other | D8: 4.99 | E8: 200.4 | F8: In-store | G8: Credit Card | H8: Walter Muller | I8: Berlin
A9: 10460 | B9: 44815 | C9: Burgers | D9: 12.99 | E9: 554.27 | F9: In-store | G9: Credit Card | H9: Remy Monet | I9: Paris
A10: 10461 | B10: 44815 | C10: Chicken Sandwiches | D10: 9.95 | E10: 201.01 | F10: In-store | G10: Credit Card | H10: Remy Monet | I10: Paris
A11: 10462 | B11: 44815 | C11: Fries | D11: 3.49 | E11: 573.07 | F11: In-store | G11: Credit Card | H11: Remy Monet | I11: Paris
A12: 10463 | B12: 44815 | C12: Beverages | D12: 2.95 | E12: 677.97 | F12: In-store | G12: Credit Card | H12: Remy Monet | I12: Paris
A13: 10464 | B13: 44815 | C13: Sides & Other | D13: 4.99 | E13: 200.4 | F13: In-store | G13: Credit Card | H13: Remy Monet | I13: Paris
... A27: 10479 | B27: 44906 | C27: Sides & Other | D27: 4.99 | E27: 200.4 | F27: In-store | G27: Credit Card | H27: Pablo Perez | I27: Madrid
A28: 10480 | B28: 13-11-2022 | C28: Burgers | D28: 12.99 | E28: 508.08 | F28: In-store | G28: Credit Card | H28: Pablo Perez | I28: Madrid
A29: 10481 | B29: 13-11-2022 | C29: Chicken Sandwiches | D29: 9.95 | E29: 201.01 | F29: In-store | G29: Credit Card | H29: Pablo Perez | I29: Madrid
A30: 10482 | B30: 13-11-2022 | C30: Fries | D30: 25.5 | E30: 630.37 | F30: In-store | G30: Credit Card | H30: Joao Silva | I30: Lisbon
A31: 10486 | B31: 14-11-2022 | C31: Chicken Sandwiches | D31: 29.05 | E31: 201.01 | F31: In-store | G31: Credit Card | H31: Joao Silva | I31: Lisbon
A32: 10487 | B32: 14-11-2022 | C32: Fries | D32: 3.49 | E32: 630.37 | F32: In-store | G32: Credit Card | H32: Joao Silva | I32: Lisbon
A33: 10488 | B33: 14-11-2022 | C33: Beverages | D33: 2.95 | E33: 677.97 | F33: In-store | G33: Credit Card | H33: Joao Silva | I33: Lisbon
A34: 10489 | B34: 14-11-2022 | C34: Sides & Other | D34: 4.99 | E34: 200.4 | F34: In-store | G34: Credit Card | H34: Pablo Perez | I34: Madrid
A35: 10490 | B35: 15-11-2022 | C35: Burgers | D35: 12.99 | E35: 508.08 | F35: In-store | G35: Credit Card | H35: Pablo Perez | I35: Madrid
A36: 10491 | B36: 15-11-2022 | C36: Chicken Sandwiches | D36: 9.95 | E36: 201.01 | F36: In-store | G36: Credit Card | H36: Pablo Perez | I36: Madrid
A37: 10492 | B37: 15-11-2022 | C37: Fries | D37: 3.49 | E37: 573.07 | F37: In-store | G37: Credit Card | H37: Pablo Perez | I37: Madrid
A38: 10493 | B38: 15-11-2022 | C38: Beverages | D38: 2.95 | E38: 677.97 | F38: In-store | G38: Credit Card | H38: Pablo Perez | I38: Madrid
A39: 10494 | B39: 15-11-2022 | C39: Sides & Other | D39: 4.99 | E39: 200.4 | F39: In-store | G39: Credit Card | H39: Pablo Perez | I39: Madrid
... A111: 10569 | B111: 30-11-2022 | C111: Sides & Other | D111: 4.99 | E111: 200.4 | F111: Online | G111: Credit Card | H111: Tom Jackson | I111: London
A112: 10570 | B112: 44573 | C112: Burgers | D112: 12.99 | E112: 492.69 | F112: Online | G112: Credit Card | H112: Tom Jackson | I112: London
A113: 10571 | B113: 44573 | C113: Chicken Sandwiches | D113: 9.95 | E113: 201.01 | F113: Online | G113: Credit Card | H113: Tom Jackson | I113: London
A114: 10572 | B114: 44573 | C114: Fries | D114: 3.49 | E114: 573.07 | F114: Online | G114: Credit Card | H114: Remy Monet | I114: Paris
A115: 10573 | B115: 44573 | C115: Beverages | D115: 2.95 | E115: 677.97 | F115: Online | G115: Credit Card | H115: Remy Monet | I115: Paris
A116: 10574 | B116: 44573 | C116: Sides & Other | D116: 4.99 | E116: 200.4 | F116: Online | G116: Credit Card | H116: Remy Monet | I116: Paris
A117: 10575 | B117: 44604 | C117: Burgers | D117: 12.99 | E117: 523.48 | F117: Online | G117: Credit Card | H117: Remy Monet | I117: Paris
A118: 10576 | B118: 44604 | C118: Chicken Sandwiches | D118: 9.95 | E118: 201.01 | F118: Online | G118: Credit Card | H118: Remy Monet | I118: Paris
A119: 10577 | B119: 44604 | C119: Fries | D119: 3.49 | E119: 630.37 | F119: Online | G119: Credit Card | H119: Remy Monet | I119: Paris
A120: 10578 | B120: 44604 | C120: Beverages | D120: 2.95 | E120: 677.97 | F120: Online | G120: Credit Card | H120: Remy Monet | I120: Paris
A121: 10579 | B121: 44604 | C121: Sides & Other | D121: 4.99 | E121: 200.4 | F121: Online | G121: Credit Card | H121: Remy Monet | I121: Paris
A122: 10580 | B122: 44632 | C122: Burgers | D122: 12.99 | E122: 523.48 | F122: Online | G122: Credit Card | H122: Remy Monet | I122: Paris
A123: 10581 | B123: 44632 | C123: Chicken Sandwiches | D123: 9.95 | E123: 201.01 | F123: Online | G123: Credit Card | H123: Remy Monet | I123: Paris
... A128: 10586 | B128: 44663 | C128: Chicken Sandwiches | D128: 9.95 | E128: 201.01 | F128: Online | G128: Credit Card | H128: Tom Jackson | I128: London
...

Sheet Charts new
A3: Row Labels | B3: Sum of Total sales
A4: November | B4: 332114.66
A5: Beverages | B5: 45600.097
A6: Burgers | B6: 150399.78
A7: Chicken Sandwiches | B7: 49840.43
A8: Fries | B8: 64274.441
A9: Sides & Other | B9: 21999.912
A10: December | B10: 437401.2
A11: Beverages | B11: 57600.166
A12: Burgers | B12: 226600.03
A13: Chicken Sandwiches | B13: 64801.266
A14: Fries | B14: 61399.849
A15: Sides & Other | B15: 26999.892
A16: Grand Total | B16: 769515.86
A18: Row Labels | B18: Sum of Total sales
A19: Berlin | B19: 100600.13
A20: Lisbon | B20: 241714.12
A21: London | B21: 211201.04
A22: Madrid | B22: 136200.27
A23: Paris | B23: 79800.305
A24: Grand Total | B24: 769515.86

Sheet Cleaned Data
A1: Order ID | B1: Date | C1: Product | D1: Price | E1: Quantity | F1: Purchase Type | G1: Payment Method | H1: Manager | I1: City | J1: Total sales | K1: Quantity Category | L1: Month
A2: 10452 | B2: 44872 | C2: Fries | D2: 3.49 | E2: 573.07 | F2: Online | G2: Gift Card | H2: Tom Jackson | I2: London | J2: ='Cleaned Data'!$D2*'Cleaned Data'!$E2 -> 2000.0143 | K2: =IF('Cleaned Data'!$E2>500,"High Quantity","Low Quantity") -> High Quantity | L2: =TEXT(B2,"mmmm") -> November
A3: 10453 | B3: 44872 | C3: Beverages | D3: 2.95 | E3: 745.76 | F3: Online | G3: Gift Card | H3: Pablo Perez | I3: Madrid | J3: ='Cleaned Data'!$D3*'Cleaned Data'!$E3 -> 2199.992 | K3: =IF('Cleaned Data'!$E3>500,"High Quantity","Low Quantity") -> High Quantity | L3: =TEXT(B3,"mmmm") -> November
A4: 10454 | B4: 44872 | C4: Sides & Other | D4: 4.99 | E4: 200.4 | F4: In-store | G4: Gift Card | H4: Joao Silva | I4: Lisbon | J4: ='Cleaned Data'!$D4*'Cleaned Data'!$E4 -> 999.996 | K4: =IF('Cleaned Data'!$E4>500,"High Quantity","Low Quantity") -> Low Quantity | L4: =TEXT(B4,"mmmm") -> November
A5: 10455 | B5: 44873 | C5: Burgers | D5: 12.99 | E5: 569.67 | F5: In-store | G5: Credit Card | H5: Walter Muller | I5: Berlin | J5: ='Cleaned Data'!$D5*'Cleaned Data'!$E5 -> 7400.0133 | K5: =IF('Cleaned Data'!$E5>500,"High Quantity","Low Quantity") -> High Quantity | L5: =TEXT(B5,"mmmm") -> November
A6: 10456 | B6: 44873 | C6: Chicken Sandwiches | D6: 9.95 | E6: 201.01 | F6: In-store | G6: Credit Card | H6: Walter Muller | I6: Berlin | J6: ='Cleaned Data'!$D6*'Cleaned Data'!$E6 -> 2000.0495 | K6: =IF('Cleaned Data'!$E6>500,"High Quantity","Low Quantity") -> Low Quantity | L6: =TEXT(B6,"mmmm") -> November
A7: 10457 | B7: 44873 | C7: Fries | D7: 3.49 | E7: 573.07 | F7: In-store | G7: Credit Card | H7: Remy Monet | I7: Paris | J7: ='Cleaned Data'!$D7*'Cleaned Data'!$E7 -> 2000.0143 | K7: =IF('Cleaned Data'!$E7>500,"High Quantity","Low Quantity") -> High Quantity | L7: =TEXT(B7,"mmmm") -> November
A8: 10459 | B8: 44873 | C8: Sides & Other | D8: 4.99 | E8: 200.4 | F8: In-store | G8: Credit Card | H8: Walter Muller | I8: Berlin | J8: ='Cleaned Data'!$D8*'Cleaned Data'!$E8 -> 999.996 | K8: =IF('Cleaned Data'!$E8>500,"High Quantity","Low Quantity") -> Low Quantity | L8: =TEXT(B8,"mmmm") -> November
A9: 10460 | B9: 44874 | C9: Burgers | D9: 12.99 | E9: 554.27 | F9: In-store | G9: Credit Card | H9: Remy Monet | I9: Paris | J9: ='Cleaned Data'!$D9*'Cleaned Data'!$E9 -> 7199.9673 | K9: =IF('Cleaned Data'!$E9>500,"High Quantity","Low Quantity") -> High Quantity | L9: =TEXT(B9,"mmmm") -> November
A10: 10461 | B10: 44874 | C10: Chicken Sandwiches | D10: 9.95 | E10: 201.01 | F10: In-store | G10: Credit Card | H10: Remy Monet | I10: Paris | J10: ='Cleaned Data'!$D10*'Cleaned Data'!$E10 -> 2000.0495 | K10: =IF('Cleaned Data'!$E10>500,"High Quantity","Low Quantity") -> Low Quantity | L10: =TEXT(B10,"mmmm") -> November
A11: 10462 | B11: 44874 | C11: Fries | D11: 3.49 | E11: 573.07 | F11: In-store | G11: Credit Card | H11: Remy Monet | I11: Paris | J11: ='Cleaned Data'!$D11*'Cleaned Data'!$E11 -> 2000.0143 | K11: =IF('Cleaned Data'!$E11>500,"High Quantity","Low Quantity") -> High Quantity | L11: =TEXT(B11,"mmmm") -> November
A12: 10463 | B12: 44874 | C12: Beverages | D12: 2.95 | E12: 677.97 | F12: In-store | G12: Credit Card | H12: Remy Monet | I12: Paris | J12: ='Cleaned Data'!$D12*'Cleaned Data'!$E12 -> 2000.0115 | K12: =IF('Cleaned Data'!$E12>500,"High Quantity","Low Quantity") -> High Quantity | L12: =TEXT(B12,"mmmm") -> November
A13: 10464 | B13: 44874 | C13: Sides & Other | D13: 4.99 | E13: 200.4 | F13: In-store | G13: Credit Card | H13: Remy Monet | I13: Paris | J13: ='Cleaned Data'!$D13*'Cleaned Data'!$E13 -> 999.996 | K13: =IF('Cleaned Data'!$E13>500,"High Quantity","Low Quantity") -> Low Quantity | L13: =TEXT(B13,"mmmm") -> November
... A255: 10713 | B255: 44924 | C255: Beverages | D255: 2.95 | E255: 677.97 | F255: Drive-thru | G255: Gift Card | H255: Walter Muller | I255: Berlin | J255: ='Cleaned Data'!$D255*'Cleaned Data'!$E255 -> 2000.0115 | K255: =IF('Cleaned Data'!$E255>500,"High Quantity","Low Quantity") -> High Quantity | L255: =TEXT(B255,"mmmm") -> December

Sheet Dashboard
A1: RESTAURANT DATA

Sheet Charts
A3: Row Labels | B3: Average of Price
A4: Beverages | B4: 2.95
A5: Burgers | B5: 12.99 | H5: Row Labels | I5: Count of Price
A6: Chicken Sandwiches | B6: 10.317308 | H6: Drive-thru | I6: 61
A7: Fries | B7: 3.9215686 | H7: In-store | I7: 86
A8: Sides & Other | B8: 4.99 | H8: Online | I8: 107
A9: Grand Total | B9: 7.1023228 | H9: Grand Total | I9: 254
A12: Row Labels | B12: Max of Price
A13: 999.996 | B13: 4.99
A14: 2000.0115 | B14: 2.95 | I14: Max of Goss sales
A15: 2000.0143 | B15: 3.49 | H15: Beverages | I15: 2199.992
A16: 2000.0495 | B16: 9.95 | H16: Burgers | I16: 9800.0457
A17: 2199.9913 | B17: 3.49 | H17: Chicken Sandwiches | I17: 5839.3405
A18: 2199.992 | B18: 2.95 | H18: Fries | I18: 16074.435
A19: 2200.0445 | B19: 9.95 | H19: Sides & Other | I19: 999.996
A20: 2400.0032 | B20: 3.49 | H20: Grand Total | I20: 16074.435
A21: Grand Total | B21: 9.95
E27: Row Labels | F27: Sum of Quantity
B28: =MIN('Cleaned Data'!D2:D255) -> 2.95 | E28: Beverages | F28: 34983.14
E29: Burgers | F29: 29022.31
E30: Chicken Sandwiches | F30: 11135.92
E31: Fries | F31: 32034.34
E32: Sides & Other | F32: 9819.6
E33: Grand Total | F33: 116995.31
E37: Row Labels | F37: Sum of Goss sales
E38: Beverages | F38: 103200.26
E39: Burgers | F39: 376999.81
E40: Chicken Sandwiches | F40: 114641.7
E41: Fries | F41: 125674.29
E42: Sides & Other | F42: 48999.804
E43: Grand Total | F43: 769515.86
F45: =GETPIVOTDATA("Goss sales",$E$37) -> 769515.86

Sheet Changelog
A1: 1.Created a copy of the dataset to clean
A2: 2.Cleaned the Manager names coloumn by removing extra space using "TRIM" function
A3: 3.Copied the newly created manager coloumn and pasted it on the orginal manager coloumn using paste special values
A4: 4.Checked the order ID coloumn to see whether there is duplicate values or not by using "CONDITIONAL FORMATTING" ,highlighting the duplication values,But did't found one.
A5: 5.Changed the datatype of coloumn"TOTAL SALES" and "PRICE" from GENERAL to CURRENCY for getter understanding
A6: 6.Created a new coloumn named "TOTAL SALES "by multiplying Quantity and price
A7: 7.This messing dataset have been cleaned and changed into aneat table and seperated the header rows for better understanding.
A8: 8.created a new coloumn nemed "QUANTITY CATEGORY" categories in to "HIGH QUANTITY" and "LOW QUANTITY" .

Sheet Questions
D6: Dashboard questions
D8: 1.Find the average Price of the all products?
D9: 2.Fine the highest Total sales value?
D10: 3.Count how many purchases were made in-store?
D11: 4.Find the highest Total sales for Credit Cart payment?
D12: 5.Which prodect has the highest Quantity?
D15: Analysis questions
D16: 1.Find the minimum price?
D17: 2.Find the average Quantity?
D18: 3.Find the total Gross Sales for Paris?
D19: 4.Find the total sales sold?

Sheet Analysis
B5: Analysis questions
B6: 1.Find the minimum price? | G6: =MIN('Cleaned Data'!D2:D255) -> 2.95
B7: 2.Find the average Quantity? | G7: =AVERAGE('Cleaned Data'!E2:E255) -> 460.61146
B8: 3.Find the total Gross Sales for Paris? | G8: =SUMIF('Cleaned Data'!I2:I255,"Paris",'Cleaned Data'!J2:J255) -> 79800.305
B9: 4.Find the total sales sold? | G9: =SUM('Cleaned Data'!E2:E255) -> 116995.31

Sheet Insights
D4: Findings | L4: Recommentions
D5: 1. High Quantity Products: Fries and Chicken Sandwiches appear frequently in the sales data. | L5: 1. Keep adequate stock of high-quantity products to prevent shortages.
D6: 2. Low Quantity Products: Some products, such as Beverages and Sides & Other, show lower quantities in the displayed records. | L6: 2. Promote low-quantity products using discounts or combo offers.
D7: 3. Sales by City: Sales records include cities such as Paris, Madrid, Berlin, and Lisbon. | L7: 3. Analyze sales by city and focus promotions on locations with stronger sales.
D8: 4. Payment Methods: Credit Card and Gift Card are commonly used payment methods. | L8: 4. Continue supporting popular payment methods while encouraging convenient digital payments.
D9: 5. Sales Channels: Both In-store and Online purchases are present. | L9: 5. Compare online vs. in-store sales to identify the stronger sales channel.
